Traceback (most recent call last):
  File "C:\Users\carol\AppData\Local\Programs\Python\Python311\Lib\site-packages\urllib3\connectionpool.py", line 715, in urlopen
    httplib_response = self._make_request(
                       ^^^^^^^^^^^^^^^^^^^
  File "C:\Users\carol\AppData\Local\Programs\Python\Python311\Lib\site-packages\urllib3\connectionpool.py", line 404, in _make_request
    self._validate_conn(conn)
  File "C:\Users\carol\AppData\Local\Programs\Python\Python311\Lib\site-packages\urllib3\connectionpool.py", line 1060, in _validate_conn
    conn.connect()
  File "C:\Users\carol\AppData\Local\Programs\Python\Python311\Lib\site-packages\urllib3\connection.py", line 419, in connect
    self.sock = ssl_wrap_socket(
                ^^^^^^^^^^^^^^^^
  File "C:\Users\carol\AppData\Local\Programs\Python\Python311\Lib\site-packages\urllib3\util\ssl_.py", line 449, in ssl_wrap_socket
    ssl_sock = _ssl_wrap_socket_impl(
               ^^^^^^^^^^^^^^^^^^^^^^
  File "C:\Users\carol\AppData\Local\Programs\Python\Python311\Lib\site-packages\urllib3\util\ssl_.py", line 493, in _ssl_wrap_socket_impl
    return ssl_context.wrap_socket(sock, server_hostname=server_hostname)
           ^^^^^^^^^^^^^^^^^^^^^^^^^^^^^^^^^^^^^^^^^^^^^^^^^^^^^^^^^^^^^^
  File "C:\Users\carol\AppData\Local\Programs\Python\Python311\Lib\ssl.py", line 517, in wrap_socket
    return self.sslsocket_class._create(
           ^^^^^^^^^^^^^^^^^^^^^^^^^^^^^
  File "C:\Users\carol\AppData\Local\Programs\Python\Python311\Lib\ssl.py", line 1075, in _create
    self.do_handshake()
  File "C:\Users\carol\AppData\Local\Programs\Python\Python311\Lib\ssl.py", line 1346, in do_handshake
    self._sslobj.do_handshake()
ConnectionAbortedError: [WinError 10053] An established connection was aborted by the software in your host machine

During handling of the above exception, another exception occurred:

Traceback (most recent call last):
  File "C:\Users\carol\AppData\Local\Programs\Python\Python311\Lib\site-packages\requests\adapters.py", line 486, in send
    resp = conn.urlopen(
           ^^^^^^^^^^^^^
  File "C:\Users\carol\AppData\Local\Programs\Python\Python311\Lib\site-packages\urllib3\connectionpool.py", line 801, in urlopen
    retries = retries.increment(
              ^^^^^^^^^^^^^^^^^^
  File "C:\Users\carol\AppData\Local\Programs\Python\Python311\Lib\site-packages\urllib3\util\retry.py", line 552, in increment
    raise six.reraise(type(error), error, _stacktrace)
          ^^^^^^^^^^^^^^^^^^^^^^^^^^^^^^^^^^^^^^^^^^^^
  File "C:\Users\carol\AppData\Local\Programs\Python\Python311\Lib\site-packages\urllib3\packages\six.py", line 769, in reraise
    raise value.with_traceback(tb)
  File "C:\Users\carol\AppData\Local\Programs\Python\Python311\Lib\site-packages\urllib3\connectionpool.py", line 715, in urlopen
    httplib_response = self._make_request(
                       ^^^^^^^^^^^^^^^^^^^
  File "C:\Users\carol\AppData\Local\Programs\Python\Python311\Lib\site-packages\urllib3\connectionpool.py", line 404, in _make_request
    self._validate_conn(conn)
  File "C:\Users\carol\AppData\Local\Programs\Python\Python311\Lib\site-packages\urllib3\connectionpool.py", line 1060, in _validate_conn
    conn.connect()
  File "C:\Users\carol\AppData\Local\Programs\Python\Python311\Lib\site-packages\urllib3\connection.py", line 419, in connect
    self.sock = ssl_wrap_socket(
                ^^^^^^^^^^^^^^^^
  File "C:\Users\carol\AppData\Local\Programs\Python\Python311\Lib\site-packages\urllib3\util\ssl_.py", line 449, in ssl_wrap_socket
    ssl_sock = _ssl_wrap_socket_impl(
               ^^^^^^^^^^^^^^^^^^^^^^
  File "C:\Users\carol\AppData\Local\Programs\Python\Python311\Lib\site-packages\urllib3\util\ssl_.py", line 493, in _ssl_wrap_socket_impl
    return ssl_context.wrap_socket(sock, server_hostname=server_hostname)
           ^^^^^^^^^^^^^^^^^^^^^^^^^^^^^^^^^^^^^^^^^^^^^^^^^^^^^^^^^^^^^^
  File "C:\Users\carol\AppData\Local\Programs\Python\Python311\Lib\ssl.py", line 517, in wrap_socket
    return self.sslsocket_class._create(
           ^^^^^^^^^^^^^^^^^^^^^^^^^^^^^
  File "C:\Users\carol\AppData\Local\Programs\Python\Python311\Lib\ssl.py", line 1075, in _create
    self.do_handshake()
  File "C:\Users\carol\AppData\Local\Programs\Python\Python311\Lib\ssl.py", line 1346, in do_handshake
    self._sslobj.do_handshake()
urllib3.exceptions.ProtocolError: ('Connection aborted.', ConnectionAbortedError(10053, 'An established connection was aborted by the software in your host machine', None, 10053, None))

During handling of the above exception, another exception occurred:

Traceback (most recent call last):
  File "C:\Users\carol\AppData\Local\Programs\Python\Python311\Lib\site-packages\webdriver_manager\core\http.py", line 32, in get
    resp = requests.get(
           ^^^^^^^^^^^^^
  File "C:\Users\carol\AppData\Local\Programs\Python\Python311\Lib\site-packages\requests\api.py", line 73, in get
    return request("get", url, params=params, **kwargs)
           ^^^^^^^^^^^^^^^^^^^^^^^^^^^^^^^^^^^^^^^^^^^^
  File "C:\Users\carol\AppData\Local\Programs\Python\Python311\Lib\site-packages\requests\api.py", line 59, in request
    return session.request(method=method, url=url, **kwargs)
           ^^^^^^^^^^^^^^^^^^^^^^^^^^^^^^^^^^^^^^^^^^^^^^^^^
  File "C:\Users\carol\AppData\Local\Programs\Python\Python311\Lib\site-packages\requests\sessions.py", line 589, in request
    resp = self.send(prep, **send_kwargs)
           ^^^^^^^^^^^^^^^^^^^^^^^^^^^^^^
  File "C:\Users\carol\AppData\Local\Programs\Python\Python311\Lib\site-packages\requests\sessions.py", line 703, in send
    r = adapter.send(request, **kwargs)
        ^^^^^^^^^^^^^^^^^^^^^^^^^^^^^^^
  File "C:\Users\carol\AppData\Local\Programs\Python\Python311\Lib\site-packages\requests\adapters.py", line 501, in send
    raise ConnectionError(err, request=request)
requests.exceptions.ConnectionError: ('Connection aborted.', ConnectionAbortedError(10053, 'An established connection was aborted by the software in your host machine', None, 10053, None))

During handling of the above exception, another exception occurred:

Traceback (most recent call last):
  File "C:\Users\carol\lion-dine\lion-dine\lion-dine\scrape.py", line 211, in <module>
    scrape_and_save()
  File "C:\Users\carol\lion-dine\lion-dine\lion-dine\scrape.py", line 194, in scrape_and_save
    data = scrape_all()
           ^^^^^^^^^^^^
  File "C:\Users\carol\lion-dine\lion-dine\lion-dine\scrape.py", line 183, in scrape_all
    hall_data = scrape_columbia(hall)
                ^^^^^^^^^^^^^^^^^^^^^
  File "C:\Users\carol\lion-dine\lion-dine\lion-dine\scrape.py", line 99, in scrape_columbia
    with managed_webdriver() as driver:
  File "C:\Users\carol\AppData\Local\Programs\Python\Python311\Lib\contextlib.py", line 137, in __enter__
    return next(self.gen)
           ^^^^^^^^^^^^^^
  File "C:\Users\carol\lion-dine\lion-dine\lion-dine\scrape.py", line 83, in managed_webdriver
    service = ChromeService(ChromeDriverManager().install())
                            ^^^^^^^^^^^^^^^^^^^^^^^^^^^^^^^
  File "C:\Users\carol\AppData\Local\Programs\Python\Python311\Lib\site-packages\webdriver_manager\chrome.py", line 40, in install
    driver_path = self._get_driver_binary_path(self.driver)
                  ^^^^^^^^^^^^^^^^^^^^^^^^^^^^^^^^^^^^^^^^^
  File "C:\Users\carol\AppData\Local\Programs\Python\Python311\Lib\site-packages\webdriver_manager\core\manager.py", line 35, in _get_driver_binary_path
    binary_path = self._cache_manager.find_driver(driver)
                  ^^^^^^^^^^^^^^^^^^^^^^^^^^^^^^^^^^^^^^^
  File "C:\Users\carol\AppData\Local\Programs\Python\Python311\Lib\site-packages\webdriver_manager\core\driver_cache.py", line 107, in find_driver
    driver_version = self.get_cache_key_driver_version(driver)
                     ^^^^^^^^^^^^^^^^^^^^^^^^^^^^^^^^^^^^^^^^^
  File "C:\Users\carol\AppData\Local\Programs\Python\Python311\Lib\site-packages\webdriver_manager\core\driver_cache.py", line 154, in get_cache_key_driver_version
    return driver.get_driver_version_to_download()
           ^^^^^^^^^^^^^^^^^^^^^^^^^^^^^^^^^^^^^^^
  File "C:\Users\carol\AppData\Local\Programs\Python\Python311\Lib\site-packages\webdriver_manager\core\driver.py", line 48, in get_driver_version_to_download
    return self.get_latest_release_version()
           ^^^^^^^^^^^^^^^^^^^^^^^^^^^^^^^^^
  File "C:\Users\carol\AppData\Local\Programs\Python\Python311\Lib\site-packages\webdriver_manager\drivers\chrome.py", line 59, in get_latest_release_version
    response = self._http_client.get(url)
               ^^^^^^^^^^^^^^^^^^^^^^^^^^
  File "C:\Users\carol\AppData\Local\Programs\Python\Python311\Lib\site-packages\webdriver_manager\core\http.py", line 35, in get
    raise exceptions.ConnectionError(f"Could not reach host. Are you offline?")
requests.exceptions.ConnectionError: Could not reach host. Are you offline?
